2025-06-11 07:10:47 [DEBUG] image_generation: Started: image_llm
2025-06-11 07:10:47 [INFO] image_generation: image_llm took 0.000 seconds
2025-06-11 07:10:55 [ERROR] image_generation: Image generation failed: [Errno 21] Is a directory: 'image_data'
Traceback (most recent call last):
  File "/home/delin/Coding/pwani_oil/llm/image_generation.py", line 25, in image_llm
    with image_path.open("rb") as f:
         ^^^^^^^^^^^^^^^^^^^^^
  File "/home/delin/anaconda3/envs/AI_projects/lib/python3.12/pathlib.py", line 1013, in open
    return io.open(self, mode, buffering, encoding, errors, newline)
           ^^^^^^^^^^^^^^^^^^^^^^^^^^^^^^^^^^^^^^^^^^^^^^^^^^^^^^^^^
IsADirectoryError: [Errno 21] Is a directory: 'image_data'
2025-06-11 07:14:01 [DEBUG] image_generation: Started: image_llm
2025-06-11 07:14:01 [INFO] image_generation: image_llm took 0.000 seconds
2025-06-11 07:15:39 [DEBUG] image_generation: Started: image_llm
2025-06-11 07:15:39 [INFO] image_generation: image_llm took 0.009 seconds
2025-06-11 07:17:05 [DEBUG] image_generation: Started: image_llm
2025-06-11 07:17:05 [INFO] image_generation: image_llm took 0.000 seconds
2025-06-11 07:40:22 [INFO] image_generation: /image latency: 101.781 sec
2025-06-11 07:41:54 [INFO] image_generation: /image latency: 92.024 sec
2025-06-11 07:43:31 [INFO] image_generation: /image latency: 97.250 sec
2025-06-11 07:51:16 [INFO] image_generation: /prompt_generator: 19.109 sec
2025-06-11 07:52:30 [INFO] image_generation: /image model only: 74.485 sec
2025-06-11 07:52:46 [INFO] image_generation: /prompt_generator: 15.706 sec
2025-06-11 07:54:06 [INFO] image_generation: /image model only: 79.725 sec
2025-06-11 07:54:26 [INFO] image_generation: /prompt_generator: 20.501 sec
2025-06-11 07:55:43 [INFO] image_generation: /image model only: 77.251 sec
2025-06-11 12:46:20 [ERROR] image_generation: Image generation failed: [Errno 21] Is a directory: '.'
Traceback (most recent call last):
  File "/home/delin/Coding/pwani_oil/llm/image_generation.py", line 25, in image_llm
    with image_path.open("rb") as f:
         ^^^^^^^^^^^^^^^^^^^^^
  File "/home/delin/anaconda3/envs/AI_projects/lib/python3.12/pathlib.py", line 1013, in open
    return io.open(self, mode, buffering, encoding, errors, newline)
           ^^^^^^^^^^^^^^^^^^^^^^^^^^^^^^^^^^^^^^^^^^^^^^^^^^^^^^^^^
IsADirectoryError: [Errno 21] Is a directory: '.'
2025-06-11 12:47:38 [ERROR] image_generation: Image generation failed: [Errno 21] Is a directory: '.'
Traceback (most recent call last):
  File "/home/delin/Coding/pwani_oil/llm/image_generation.py", line 25, in image_llm
    with image_path.open("rb") as f:
         ^^^^^^^^^^^^^^^^^^^^^
  File "/home/delin/anaconda3/envs/AI_projects/lib/python3.12/pathlib.py", line 1013, in open
    return io.open(self, mode, buffering, encoding, errors, newline)
           ^^^^^^^^^^^^^^^^^^^^^^^^^^^^^^^^^^^^^^^^^^^^^^^^^^^^^^^^^
IsADirectoryError: [Errno 21] Is a directory: '.'
2025-06-11 12:52:42 [ERROR] image_generation: Image generation failed: [Errno 21] Is a directory: '.'
Traceback (most recent call last):
  File "/home/delin/Coding/pwani_oil/llm/image_generation.py", line 25, in image_llm
    with image_path.open("rb") as f:
         ^^^^^^^^^^^^^^^^^^^^^
  File "/home/delin/anaconda3/envs/AI_projects/lib/python3.12/pathlib.py", line 1013, in open
    return io.open(self, mode, buffering, encoding, errors, newline)
           ^^^^^^^^^^^^^^^^^^^^^^^^^^^^^^^^^^^^^^^^^^^^^^^^^^^^^^^^^
IsADirectoryError: [Errno 21] Is a directory: '.'
2025-06-11 12:59:44 [INFO] image_generation: /prompt_generator_llm: 156.768 sec
2025-06-11 12:59:44 [INFO] image_generation: /prompt_generator complete: 162.223 sec
2025-06-11 13:01:05 [INFO] image_generation: /image model only: 80.926 sec
2025-06-11 13:01:24 [INFO] image_generation: /prompt_generator_llm: 13.159 sec
2025-06-11 13:01:24 [INFO] image_generation: /prompt_generator complete: 18.182 sec
2025-06-11 13:02:43 [INFO] image_generation: /image model only: 79.048 sec
2025-06-11 13:03:00 [INFO] image_generation: /prompt_generator_llm: 12.158 sec
2025-06-11 13:03:00 [INFO] image_generation: /prompt_generator complete: 17.454 sec
2025-06-11 13:04:27 [INFO] image_generation: /image model only: 87.419 sec
2025-06-11 13:10:39 [ERROR] image_generation: Image generation failed: 'coroutine' object has no attribute 'content'
Traceback (most recent call last):
  File "/home/delin/Coding/pwani_oil/llm/image_generation.py", line 79, in image_llm
    prompt= await llm.ainvoke(messages).content
                  ^^^^^^^^^^^^^^^^^^^^^^^^^^^^^
AttributeError: 'coroutine' object has no attribute 'content'
2025-06-11 13:52:19 [INFO] image_generation: /prompt_generator_llm: 9.695 sec
2025-06-11 13:52:19 [INFO] image_generation: /prompt_generator complete: 9.882 sec
2025-06-11 13:53:40 [INFO] image_generation: /image model only: 80.538 sec
2025-06-11 13:53:51 [INFO] image_generation: /prompt_generator_llm: 11.641 sec
2025-06-11 13:53:51 [INFO] image_generation: /prompt_generator complete: 11.667 sec
2025-06-11 13:55:15 [INFO] image_generation: /image model only: 83.617 sec
2025-06-11 13:55:31 [INFO] image_generation: /prompt_generator_llm: 13.688 sec
2025-06-11 13:55:31 [INFO] image_generation: /prompt_generator complete: 16.418 sec
2025-06-11 13:56:46 [INFO] image_generation: /image model only: 74.918 sec
2025-06-11 13:58:58 [INFO] image_generation: /prompt_generator_llm: 10.011 sec
2025-06-11 13:58:58 [INFO] image_generation: /prompt_generator complete: 10.048 sec
2025-06-11 14:00:03 [INFO] image_generation: /prompt_generator_llm: 13.563 sec
2025-06-11 14:00:03 [INFO] image_generation: /prompt_generator complete: 13.716 sec
2025-06-11 14:11:56 [ERROR] image_generation: Image generation failed: [Errno 21] Is a directory: '.'
Traceback (most recent call last):
  File "/home/delin/Coding/pwani_oil/llm/image_generation.py", line 27, in image_llm
    async with aiofiles.open(image_path, "rb") as f:
               ^^^^^^^^^^^^^^^^^^^^^^^^^^^^^^^
  File "/home/delin/anaconda3/envs/AI_projects/lib/python3.12/site-packages/aiofiles/base.py", line 63, in __aenter__
    return await self
           ^^^^^^^^^^
  File "/home/delin/anaconda3/envs/AI_projects/lib/python3.12/site-packages/aiofiles/base.py", line 59, in __await__
    self._obj = yield from self._coro.__await__()
                ^^^^^^^^^^^^^^^^^^^^^^^^^^^^^^^^^
  File "/home/delin/anaconda3/envs/AI_projects/lib/python3.12/site-packages/aiofiles/threadpool/__init__.py", line 92, in _open
    f = await loop.run_in_executor(executor, cb)
        ^^^^^^^^^^^^^^^^^^^^^^^^^^^^^^^^^^^^^^^^
  File "/home/delin/anaconda3/envs/AI_projects/lib/python3.12/concurrent/futures/thread.py", line 59, in run
    result = self.fn(*self.args, **self.kwargs)
             ^^^^^^^^^^^^^^^^^^^^^^^^^^^^^^^^^^
IsADirectoryError: [Errno 21] Is a directory: '.'
2025-06-11 14:12:04 [ERROR] image_generation: Image generation failed: [Errno 21] Is a directory: '.'
Traceback (most recent call last):
  File "/home/delin/Coding/pwani_oil/llm/image_generation.py", line 27, in image_llm
    async with aiofiles.open(image_path, "rb") as f:
               ^^^^^^^^^^^^^^^^^^^^^^^^^^^^^^^
  File "/home/delin/anaconda3/envs/AI_projects/lib/python3.12/site-packages/aiofiles/base.py", line 63, in __aenter__
    return await self
           ^^^^^^^^^^
  File "/home/delin/anaconda3/envs/AI_projects/lib/python3.12/site-packages/aiofiles/base.py", line 59, in __await__
    self._obj = yield from self._coro.__await__()
                ^^^^^^^^^^^^^^^^^^^^^^^^^^^^^^^^^
  File "/home/delin/anaconda3/envs/AI_projects/lib/python3.12/site-packages/aiofiles/threadpool/__init__.py", line 92, in _open
    f = await loop.run_in_executor(executor, cb)
        ^^^^^^^^^^^^^^^^^^^^^^^^^^^^^^^^^^^^^^^^
  File "/home/delin/anaconda3/envs/AI_projects/lib/python3.12/concurrent/futures/thread.py", line 59, in run
    result = self.fn(*self.args, **self.kwargs)
             ^^^^^^^^^^^^^^^^^^^^^^^^^^^^^^^^^^
IsADirectoryError: [Errno 21] Is a directory: '.'
2025-06-11 14:12:05 [ERROR] image_generation: Image generation failed: [Errno 21] Is a directory: '.'
Traceback (most recent call last):
  File "/home/delin/Coding/pwani_oil/llm/image_generation.py", line 27, in image_llm
    async with aiofiles.open(image_path, "rb") as f:
               ^^^^^^^^^^^^^^^^^^^^^^^^^^^^^^^
  File "/home/delin/anaconda3/envs/AI_projects/lib/python3.12/site-packages/aiofiles/base.py", line 63, in __aenter__
    return await self
           ^^^^^^^^^^
  File "/home/delin/anaconda3/envs/AI_projects/lib/python3.12/site-packages/aiofiles/base.py", line 59, in __await__
    self._obj = yield from self._coro.__await__()
                ^^^^^^^^^^^^^^^^^^^^^^^^^^^^^^^^^
  File "/home/delin/anaconda3/envs/AI_projects/lib/python3.12/site-packages/aiofiles/threadpool/__init__.py", line 92, in _open
    f = await loop.run_in_executor(executor, cb)
        ^^^^^^^^^^^^^^^^^^^^^^^^^^^^^^^^^^^^^^^^
  File "/home/delin/anaconda3/envs/AI_projects/lib/python3.12/concurrent/futures/thread.py", line 59, in run
    result = self.fn(*self.args, **self.kwargs)
             ^^^^^^^^^^^^^^^^^^^^^^^^^^^^^^^^^^
IsADirectoryError: [Errno 21] Is a directory: '.'
2025-06-11 14:12:05 [ERROR] image_generation: Image generation failed: [Errno 21] Is a directory: '.'
Traceback (most recent call last):
  File "/home/delin/Coding/pwani_oil/llm/image_generation.py", line 27, in image_llm
    async with aiofiles.open(image_path, "rb") as f:
               ^^^^^^^^^^^^^^^^^^^^^^^^^^^^^^^
  File "/home/delin/anaconda3/envs/AI_projects/lib/python3.12/site-packages/aiofiles/base.py", line 63, in __aenter__
    return await self
           ^^^^^^^^^^
  File "/home/delin/anaconda3/envs/AI_projects/lib/python3.12/site-packages/aiofiles/base.py", line 59, in __await__
    self._obj = yield from self._coro.__await__()
                ^^^^^^^^^^^^^^^^^^^^^^^^^^^^^^^^^
  File "/home/delin/anaconda3/envs/AI_projects/lib/python3.12/site-packages/aiofiles/threadpool/__init__.py", line 92, in _open
    f = await loop.run_in_executor(executor, cb)
        ^^^^^^^^^^^^^^^^^^^^^^^^^^^^^^^^^^^^^^^^
  File "/home/delin/anaconda3/envs/AI_projects/lib/python3.12/concurrent/futures/thread.py", line 59, in run
    result = self.fn(*self.args, **self.kwargs)
             ^^^^^^^^^^^^^^^^^^^^^^^^^^^^^^^^^^
IsADirectoryError: [Errno 21] Is a directory: '.'
2025-06-11 14:12:05 [ERROR] image_generation: Image generation failed: [Errno 21] Is a directory: '.'
Traceback (most recent call last):
  File "/home/delin/Coding/pwani_oil/llm/image_generation.py", line 27, in image_llm
    async with aiofiles.open(image_path, "rb") as f:
               ^^^^^^^^^^^^^^^^^^^^^^^^^^^^^^^
  File "/home/delin/anaconda3/envs/AI_projects/lib/python3.12/site-packages/aiofiles/base.py", line 63, in __aenter__
    return await self
           ^^^^^^^^^^
  File "/home/delin/anaconda3/envs/AI_projects/lib/python3.12/site-packages/aiofiles/base.py", line 59, in __await__
    self._obj = yield from self._coro.__await__()
                ^^^^^^^^^^^^^^^^^^^^^^^^^^^^^^^^^
  File "/home/delin/anaconda3/envs/AI_projects/lib/python3.12/site-packages/aiofiles/threadpool/__init__.py", line 92, in _open
    f = await loop.run_in_executor(executor, cb)
        ^^^^^^^^^^^^^^^^^^^^^^^^^^^^^^^^^^^^^^^^
  File "/home/delin/anaconda3/envs/AI_projects/lib/python3.12/concurrent/futures/thread.py", line 59, in run
    result = self.fn(*self.args, **self.kwargs)
             ^^^^^^^^^^^^^^^^^^^^^^^^^^^^^^^^^^
IsADirectoryError: [Errno 21] Is a directory: '.'
2025-06-11 14:12:06 [ERROR] image_generation: Image generation failed: [Errno 21] Is a directory: '.'
Traceback (most recent call last):
  File "/home/delin/Coding/pwani_oil/llm/image_generation.py", line 27, in image_llm
    async with aiofiles.open(image_path, "rb") as f:
               ^^^^^^^^^^^^^^^^^^^^^^^^^^^^^^^
  File "/home/delin/anaconda3/envs/AI_projects/lib/python3.12/site-packages/aiofiles/base.py", line 63, in __aenter__
    return await self
           ^^^^^^^^^^
  File "/home/delin/anaconda3/envs/AI_projects/lib/python3.12/site-packages/aiofiles/base.py", line 59, in __await__
    self._obj = yield from self._coro.__await__()
                ^^^^^^^^^^^^^^^^^^^^^^^^^^^^^^^^^
  File "/home/delin/anaconda3/envs/AI_projects/lib/python3.12/site-packages/aiofiles/threadpool/__init__.py", line 92, in _open
    f = await loop.run_in_executor(executor, cb)
        ^^^^^^^^^^^^^^^^^^^^^^^^^^^^^^^^^^^^^^^^
  File "/home/delin/anaconda3/envs/AI_projects/lib/python3.12/concurrent/futures/thread.py", line 59, in run
    result = self.fn(*self.args, **self.kwargs)
             ^^^^^^^^^^^^^^^^^^^^^^^^^^^^^^^^^^
IsADirectoryError: [Errno 21] Is a directory: '.'
2025-06-11 14:12:06 [ERROR] image_generation: Image generation failed: [Errno 21] Is a directory: '.'
Traceback (most recent call last):
  File "/home/delin/Coding/pwani_oil/llm/image_generation.py", line 27, in image_llm
    async with aiofiles.open(image_path, "rb") as f:
               ^^^^^^^^^^^^^^^^^^^^^^^^^^^^^^^
  File "/home/delin/anaconda3/envs/AI_projects/lib/python3.12/site-packages/aiofiles/base.py", line 63, in __aenter__
    return await self
           ^^^^^^^^^^
  File "/home/delin/anaconda3/envs/AI_projects/lib/python3.12/site-packages/aiofiles/base.py", line 59, in __await__
    self._obj = yield from self._coro.__await__()
                ^^^^^^^^^^^^^^^^^^^^^^^^^^^^^^^^^
  File "/home/delin/anaconda3/envs/AI_projects/lib/python3.12/site-packages/aiofiles/threadpool/__init__.py", line 92, in _open
    f = await loop.run_in_executor(executor, cb)
        ^^^^^^^^^^^^^^^^^^^^^^^^^^^^^^^^^^^^^^^^
  File "/home/delin/anaconda3/envs/AI_projects/lib/python3.12/concurrent/futures/thread.py", line 59, in run
    result = self.fn(*self.args, **self.kwargs)
             ^^^^^^^^^^^^^^^^^^^^^^^^^^^^^^^^^^
IsADirectoryError: [Errno 21] Is a directory: '.'
2025-06-11 14:12:09 [ERROR] image_generation: Image generation failed: [Errno 21] Is a directory: '.'
Traceback (most recent call last):
  File "/home/delin/Coding/pwani_oil/llm/image_generation.py", line 27, in image_llm
    async with aiofiles.open(image_path, "rb") as f:
               ^^^^^^^^^^^^^^^^^^^^^^^^^^^^^^^
  File "/home/delin/anaconda3/envs/AI_projects/lib/python3.12/site-packages/aiofiles/base.py", line 63, in __aenter__
    return await self
           ^^^^^^^^^^
  File "/home/delin/anaconda3/envs/AI_projects/lib/python3.12/site-packages/aiofiles/base.py", line 59, in __await__
    self._obj = yield from self._coro.__await__()
                ^^^^^^^^^^^^^^^^^^^^^^^^^^^^^^^^^
  File "/home/delin/anaconda3/envs/AI_projects/lib/python3.12/site-packages/aiofiles/threadpool/__init__.py", line 92, in _open
    f = await loop.run_in_executor(executor, cb)
        ^^^^^^^^^^^^^^^^^^^^^^^^^^^^^^^^^^^^^^^^
  File "/home/delin/anaconda3/envs/AI_projects/lib/python3.12/concurrent/futures/thread.py", line 59, in run
    result = self.fn(*self.args, **self.kwargs)
             ^^^^^^^^^^^^^^^^^^^^^^^^^^^^^^^^^^
IsADirectoryError: [Errno 21] Is a directory: '.'
2025-06-11 14:12:09 [ERROR] image_generation: Image generation failed: [Errno 21] Is a directory: '.'
Traceback (most recent call last):
  File "/home/delin/Coding/pwani_oil/llm/image_generation.py", line 27, in image_llm
    async with aiofiles.open(image_path, "rb") as f:
               ^^^^^^^^^^^^^^^^^^^^^^^^^^^^^^^
  File "/home/delin/anaconda3/envs/AI_projects/lib/python3.12/site-packages/aiofiles/base.py", line 63, in __aenter__
    return await self
           ^^^^^^^^^^
  File "/home/delin/anaconda3/envs/AI_projects/lib/python3.12/site-packages/aiofiles/base.py", line 59, in __await__
    self._obj = yield from self._coro.__await__()
                ^^^^^^^^^^^^^^^^^^^^^^^^^^^^^^^^^
  File "/home/delin/anaconda3/envs/AI_projects/lib/python3.12/site-packages/aiofiles/threadpool/__init__.py", line 92, in _open
    f = await loop.run_in_executor(executor, cb)
        ^^^^^^^^^^^^^^^^^^^^^^^^^^^^^^^^^^^^^^^^
  File "/home/delin/anaconda3/envs/AI_projects/lib/python3.12/concurrent/futures/thread.py", line 59, in run
    result = self.fn(*self.args, **self.kwargs)
             ^^^^^^^^^^^^^^^^^^^^^^^^^^^^^^^^^^
IsADirectoryError: [Errno 21] Is a directory: '.'
2025-06-11 14:12:09 [ERROR] image_generation: Image generation failed: [Errno 21] Is a directory: '.'
Traceback (most recent call last):
  File "/home/delin/Coding/pwani_oil/llm/image_generation.py", line 27, in image_llm
    async with aiofiles.open(image_path, "rb") as f:
               ^^^^^^^^^^^^^^^^^^^^^^^^^^^^^^^
  File "/home/delin/anaconda3/envs/AI_projects/lib/python3.12/site-packages/aiofiles/base.py", line 63, in __aenter__
    return await self
           ^^^^^^^^^^
  File "/home/delin/anaconda3/envs/AI_projects/lib/python3.12/site-packages/aiofiles/base.py", line 59, in __await__
    self._obj = yield from self._coro.__await__()
                ^^^^^^^^^^^^^^^^^^^^^^^^^^^^^^^^^
  File "/home/delin/anaconda3/envs/AI_projects/lib/python3.12/site-packages/aiofiles/threadpool/__init__.py", line 92, in _open
    f = await loop.run_in_executor(executor, cb)
        ^^^^^^^^^^^^^^^^^^^^^^^^^^^^^^^^^^^^^^^^
  File "/home/delin/anaconda3/envs/AI_projects/lib/python3.12/concurrent/futures/thread.py", line 59, in run
    result = self.fn(*self.args, **self.kwargs)
             ^^^^^^^^^^^^^^^^^^^^^^^^^^^^^^^^^^
IsADirectoryError: [Errno 21] Is a directory: '.'
2025-06-11 14:12:09 [ERROR] image_generation: Image generation failed: [Errno 21] Is a directory: '.'
Traceback (most recent call last):
  File "/home/delin/Coding/pwani_oil/llm/image_generation.py", line 27, in image_llm
    async with aiofiles.open(image_path, "rb") as f:
               ^^^^^^^^^^^^^^^^^^^^^^^^^^^^^^^
  File "/home/delin/anaconda3/envs/AI_projects/lib/python3.12/site-packages/aiofiles/base.py", line 63, in __aenter__
    return await self
           ^^^^^^^^^^
  File "/home/delin/anaconda3/envs/AI_projects/lib/python3.12/site-packages/aiofiles/base.py", line 59, in __await__
    self._obj = yield from self._coro.__await__()
                ^^^^^^^^^^^^^^^^^^^^^^^^^^^^^^^^^
  File "/home/delin/anaconda3/envs/AI_projects/lib/python3.12/site-packages/aiofiles/threadpool/__init__.py", line 92, in _open
    f = await loop.run_in_executor(executor, cb)
        ^^^^^^^^^^^^^^^^^^^^^^^^^^^^^^^^^^^^^^^^
  File "/home/delin/anaconda3/envs/AI_projects/lib/python3.12/concurrent/futures/thread.py", line 59, in run
    result = self.fn(*self.args, **self.kwargs)
             ^^^^^^^^^^^^^^^^^^^^^^^^^^^^^^^^^^
IsADirectoryError: [Errno 21] Is a directory: '.'
2025-06-11 14:13:22 [INFO] image_generation: /prompt_generator_llm: 13.336 sec
2025-06-11 14:13:22 [INFO] image_generation: /prompt_generator complete: 13.385 sec
2025-06-11 14:13:22 [INFO] image_generation: /image model only: 0.006 sec
2025-06-11 14:13:22 [ERROR] image_generation: Image generation failed: 'coroutine' object has no attribute 'data'
Traceback (most recent call last):
  File "/home/delin/Coding/pwani_oil/llm/image_generation.py", line 104, in image_llm
    return img.data[0].b64_json,prompt
           ^^^^^^^^
AttributeError: 'coroutine' object has no attribute 'data'
2025-06-11 14:19:50 [INFO] image_generation: /prompt_generator_llm: 18.370 sec
2025-06-11 14:19:50 [INFO] image_generation: /prompt_generator complete: 18.511 sec
2025-06-11 14:21:37 [INFO] image_generation: Started Image generateion
2025-06-11 14:21:50 [INFO] image_generation: /prompt_generator_llm: 12.542 sec
2025-06-11 14:21:50 [INFO] image_generation: /prompt_generator complete: 12.696 sec
2025-06-11 14:27:24 [INFO] image_generation: Started Image generateion
2025-06-11 14:27:35 [INFO] image_generation: /prompt_generator_llm: 11.054 sec
2025-06-11 14:27:35 [INFO] image_generation: /prompt_generator complete: 11.207 sec
2025-06-11 14:28:33 [ERROR] image_generation: Image generation failed: Error code: 500 - {'error': {'message': 'The server had an error while processing your request. Sorry about that! You can retry your request, or contact us through our help center at help.openai.com if the error persists. (Please include the request ID req_4eb7242805cb7cff147625aec00b66de in your message.)', 'type': 'server_error', 'param': None, 'code': None}}
Traceback (most recent call last):
  File "/home/delin/Coding/pwani_oil/llm/image_generation.py", line 94, in image_llm
    img = await client.images.edit(
          ^^^^^^^^^^^^^^^^^^^^^^^^^
  File "/home/delin/anaconda3/envs/AI_projects/lib/python3.12/site-packages/openai/resources/images.py", line 452, in edit
    return await self._post(
           ^^^^^^^^^^^^^^^^^
  File "/home/delin/anaconda3/envs/AI_projects/lib/python3.12/site-packages/openai/_base_client.py", line 1767, in post
    return await self.request(cast_to, opts, stream=stream, stream_cls=stream_cls)
           ^^^^^^^^^^^^^^^^^^^^^^^^^^^^^^^^^^^^^^^^^^^^^^^^^^^^^^^^^^^^^^^^^^^^^^^
  File "/home/delin/anaconda3/envs/AI_projects/lib/python3.12/site-packages/openai/_base_client.py", line 1461, in request
    return await self._request(
           ^^^^^^^^^^^^^^^^^^^^
  File "/home/delin/anaconda3/envs/AI_projects/lib/python3.12/site-packages/openai/_base_client.py", line 1547, in _request
    return await self._retry_request(
           ^^^^^^^^^^^^^^^^^^^^^^^^^^
  File "/home/delin/anaconda3/envs/AI_projects/lib/python3.12/site-packages/openai/_base_client.py", line 1594, in _retry_request
    return await self._request(
           ^^^^^^^^^^^^^^^^^^^^
  File "/home/delin/anaconda3/envs/AI_projects/lib/python3.12/site-packages/openai/_base_client.py", line 1547, in _request
    return await self._retry_request(
           ^^^^^^^^^^^^^^^^^^^^^^^^^^
  File "/home/delin/anaconda3/envs/AI_projects/lib/python3.12/site-packages/openai/_base_client.py", line 1594, in _retry_request
    return await self._request(
           ^^^^^^^^^^^^^^^^^^^^
  File "/home/delin/anaconda3/envs/AI_projects/lib/python3.12/site-packages/openai/_base_client.py", line 1562, in _request
    raise self._make_status_error_from_response(err.response) from None
openai.InternalServerError: Error code: 500 - {'error': {'message': 'The server had an error while processing your request. Sorry about that! You can retry your request, or contact us through our help center at help.openai.com if the error persists. (Please include the request ID req_4eb7242805cb7cff147625aec00b66de in your message.)', 'type': 'server_error', 'param': None, 'code': None}}
2025-06-11 14:30:32 [INFO] image_generation: Started Image generateion
2025-06-11 14:30:44 [INFO] image_generation: /prompt_generator_llm: 12.068 sec
2025-06-11 14:30:44 [INFO] image_generation: /prompt_generator complete: 12.107 sec
2025-06-11 14:34:11 [INFO] image_generation: Started Image generateion
2025-06-11 14:34:25 [INFO] image_generation: /prompt_generator_llm: 14.421 sec
2025-06-11 14:34:25 [INFO] image_generation: /prompt_generator complete: 14.627 sec
2025-06-11 14:35:47 [ERROR] image_generation: Image generation failed: Error code: 500 - {'error': {'message': 'The server had an error while processing your request. Sorry about that! You can retry your request, or contact us through our help center at help.openai.com if the error persists. (Please include the request ID req_bed69523e475ae0edd5664e57df17f92 in your message.)', 'type': 'server_error', 'param': None, 'code': None}}
Traceback (most recent call last):
  File "/home/delin/Coding/pwani_oil/llm/image_generation.py", line 94, in image_llm
    img = await client.images.edit(
          ^^^^^^^^^^^^^^^^^^^^^^^^^
  File "/home/delin/anaconda3/envs/AI_projects/lib/python3.12/site-packages/openai/resources/images.py", line 452, in edit
    return await self._post(
           ^^^^^^^^^^^^^^^^^
  File "/home/delin/anaconda3/envs/AI_projects/lib/python3.12/site-packages/openai/_base_client.py", line 1767, in post
    return await self.request(cast_to, opts, stream=stream, stream_cls=stream_cls)
           ^^^^^^^^^^^^^^^^^^^^^^^^^^^^^^^^^^^^^^^^^^^^^^^^^^^^^^^^^^^^^^^^^^^^^^^
  File "/home/delin/anaconda3/envs/AI_projects/lib/python3.12/site-packages/openai/_base_client.py", line 1461, in request
    return await self._request(
           ^^^^^^^^^^^^^^^^^^^^
  File "/home/delin/anaconda3/envs/AI_projects/lib/python3.12/site-packages/openai/_base_client.py", line 1547, in _request
    return await self._retry_request(
           ^^^^^^^^^^^^^^^^^^^^^^^^^^
  File "/home/delin/anaconda3/envs/AI_projects/lib/python3.12/site-packages/openai/_base_client.py", line 1594, in _retry_request
    return await self._request(
           ^^^^^^^^^^^^^^^^^^^^
  File "/home/delin/anaconda3/envs/AI_projects/lib/python3.12/site-packages/openai/_base_client.py", line 1547, in _request
    return await self._retry_request(
           ^^^^^^^^^^^^^^^^^^^^^^^^^^
  File "/home/delin/anaconda3/envs/AI_projects/lib/python3.12/site-packages/openai/_base_client.py", line 1594, in _retry_request
    return await self._request(
           ^^^^^^^^^^^^^^^^^^^^
  File "/home/delin/anaconda3/envs/AI_projects/lib/python3.12/site-packages/openai/_base_client.py", line 1562, in _request
    raise self._make_status_error_from_response(err.response) from None
openai.InternalServerError: Error code: 500 - {'error': {'message': 'The server had an error while processing your request. Sorry about that! You can retry your request, or contact us through our help center at help.openai.com if the error persists. (Please include the request ID req_bed69523e475ae0edd5664e57df17f92 in your message.)', 'type': 'server_error', 'param': None, 'code': None}}
2025-06-11 14:43:42 [INFO] image_generation: Started Image generateion
2025-06-11 14:43:56 [INFO] image_generation: /prompt_generator_llm: 14.410 sec
2025-06-11 14:43:56 [INFO] image_generation: /prompt_generator complete: 14.441 sec
2025-06-11 14:45:16 [INFO] image_generation: /image model only: 79.819 sec
2025-06-11 14:45:16 [INFO] image_generation: Started Image generateion
2025-06-11 14:45:26 [INFO] image_generation: /prompt_generator_llm: 10.015 sec
2025-06-11 14:45:26 [INFO] image_generation: /prompt_generator complete: 10.167 sec
2025-06-11 14:57:00 [INFO] image_generation: Started Image generateion
2025-06-11 14:57:09 [INFO] image_generation: /prompt_generator_llm: 9.450 sec
2025-06-11 14:57:09 [INFO] image_generation: /prompt_generator complete: 9.487 sec
2025-06-11 15:01:37 [INFO] image_generation: Started Image generateion
2025-06-11 15:01:47 [INFO] image_generation: /prompt_generator_llm: 10.358 sec
2025-06-11 15:01:47 [INFO] image_generation: /prompt_generator complete: 10.504 sec
2025-06-11 15:10:53 [INFO] image_generation: Started Image geenration
2025-06-11 15:11:06 [INFO] image_generation: /prompt_generator_llm: 12.330 sec
2025-06-11 15:11:06 [INFO] image_generation: /prompt_generator complete: 12.535 sec
2025-06-11 15:12:20 [INFO] image_generation: /image model only: 74.324 sec
2025-06-11 15:12:20 [INFO] image_generation: Started Image geenration
2025-06-11 15:12:30 [INFO] image_generation: /prompt_generator_llm: 9.957 sec
2025-06-11 15:12:30 [INFO] image_generation: /prompt_generator complete: 9.999 sec
2025-06-11 15:13:45 [INFO] image_generation: /image model only: 74.322 sec
2025-06-11 15:13:45 [INFO] image_generation: Started Image geenration
2025-06-11 15:13:57 [INFO] image_generation: /prompt_generator_llm: 12.464 sec
2025-06-11 15:13:57 [INFO] image_generation: /prompt_generator complete: 12.589 sec
2025-06-11 15:15:07 [INFO] image_generation: /image model only: 69.911 sec
2025-06-11 15:49:18 [INFO] image_generation: Started Image geenration
2025-06-11 15:49:26 [INFO] image_generation: /prompt_generator_llm: 7.776 sec
2025-06-11 15:49:26 [INFO] image_generation: /prompt_generator complete: 8.046 sec
2025-06-11 15:50:45 [INFO] image_generation: /image model only: 78.897 sec
2025-06-11 15:50:45 [INFO] image_generation: Started Image geenration
2025-06-11 15:50:53 [INFO] image_generation: /prompt_generator_llm: 8.802 sec
2025-06-11 15:50:53 [INFO] image_generation: /prompt_generator complete: 8.841 sec
2025-06-11 15:52:07 [INFO] image_generation: /image model only: 73.330 sec
2025-06-11 15:52:07 [INFO] image_generation: Started Image geenration
2025-06-11 15:52:14 [INFO] image_generation: /prompt_generator_llm: 6.618 sec
2025-06-11 15:52:14 [INFO] image_generation: /prompt_generator complete: 6.751 sec
2025-06-11 15:53:28 [INFO] image_generation: /image model only: 74.865 sec
2025-06-12 06:31:54 [INFO] image_generation: Started Image geenration
2025-06-12 06:32:09 [INFO] image_generation: /prompt_generator_llm: 14.480 sec
2025-06-12 06:32:09 [INFO] image_generation: /prompt_generator complete: 14.656 sec
2025-06-12 06:33:22 [INFO] image_generation: /image model only: 72.728 sec
2025-06-12 06:33:22 [INFO] image_generation: Started Image geenration
2025-06-12 06:33:35 [INFO] image_generation: /prompt_generator_llm: 13.213 sec
2025-06-12 06:33:35 [INFO] image_generation: /prompt_generator complete: 13.253 sec
2025-06-12 06:34:54 [INFO] image_generation: /image model only: 79.283 sec
2025-06-12 06:34:54 [INFO] image_generation: Started Image geenration
2025-06-12 06:35:06 [INFO] image_generation: /prompt_generator_llm: 11.281 sec
2025-06-12 06:35:06 [INFO] image_generation: /prompt_generator complete: 11.405 sec
2025-06-12 06:36:13 [INFO] image_generation: /image model only: 67.576 sec
2025-06-12 06:53:54 [INFO] image_generation: Started Image geenration
2025-06-12 06:54:03 [INFO] image_generation: /prompt_generator_llm: 9.109 sec
2025-06-12 06:54:03 [INFO] image_generation: /prompt_generator complete: 9.266 sec
2025-06-12 06:55:11 [INFO] image_generation: /image model only: 68.175 sec
2025-06-12 06:55:11 [INFO] image_generation: Started Image geenration
2025-06-12 06:57:07 [INFO] image_generation: Started Image geenration
2025-06-12 06:57:15 [INFO] image_generation: /prompt_generator_llm: 7.901 sec
2025-06-12 06:57:15 [INFO] image_generation: /prompt_generator complete: 7.919 sec
2025-06-12 06:58:18 [INFO] image_generation: /image model only: 63.032 sec
2025-06-12 06:58:18 [INFO] image_generation: Started Image geenration
2025-06-12 06:59:40 [INFO] image_generation: Started Image geenration
2025-06-12 06:59:50 [INFO] image_generation: /prompt_generator_llm: 9.887 sec
2025-06-12 06:59:50 [INFO] image_generation: /prompt_generator complete: 9.903 sec
2025-06-12 07:01:03 [INFO] image_generation: /image model only: 73.514 sec
2025-06-12 07:01:03 [INFO] image_generation: Started Image geenration
2025-06-12 07:01:12 [INFO] image_generation: /prompt_generator_llm: 9.012 sec
2025-06-12 07:01:12 [INFO] image_generation: /prompt_generator complete: 9.112 sec
2025-06-12 07:02:27 [INFO] image_generation: /image model only: 74.639 sec
2025-06-12 07:02:27 [INFO] image_generation: Started Image geenration
2025-06-12 07:02:37 [INFO] image_generation: /prompt_generator_llm: 9.652 sec
2025-06-12 07:02:37 [INFO] image_generation: /prompt_generator complete: 9.670 sec
2025-06-12 07:03:42 [INFO] image_generation: /image model only: 65.828 sec
2025-06-12 07:06:48 [INFO] image_generation: Started Image geenration
2025-06-12 07:06:55 [INFO] image_generation: /prompt_generator_llm: 6.866 sec
2025-06-12 07:06:55 [INFO] image_generation: /prompt_generator complete: 6.918 sec
2025-06-12 07:08:04 [INFO] image_generation: /image model only: 69.330 sec
2025-06-12 07:08:04 [INFO] image_generation: Started Image geenration
2025-06-12 07:08:13 [INFO] image_generation: /prompt_generator_llm: 8.459 sec
2025-06-12 07:08:13 [INFO] image_generation: /prompt_generator complete: 8.499 sec
2025-06-12 07:09:28 [INFO] image_generation: /image model only: 75.109 sec
2025-06-12 07:09:28 [INFO] image_generation: Started Image geenration
2025-06-12 07:09:37 [INFO] image_generation: /prompt_generator_llm: 8.898 sec
2025-06-12 07:09:37 [INFO] image_generation: /prompt_generator complete: 8.969 sec
2025-06-12 07:10:41 [INFO] image_generation: /image model only: 64.176 sec
2025-06-15 09:27:22 [INFO] image_generation: /image model only: 78.637 sec
