2025-06-11 07:08:24 [INFO] routes: /image latency: 0.013 sec
2025-06-11 07:08:24 [INFO] routes: 0.013601303100585938
2025-06-11 07:10:47 [INFO] routes: /image and text latency: 0.011 sec
2025-06-11 07:10:47 [INFO] routes: 0.0114593505859375
2025-06-11 07:14:01 [INFO] routes: /image and text latency: 0.014 sec
2025-06-11 07:14:01 [INFO] routes: 0.014843463897705078
2025-06-11 07:38:34 [INFO] routes: /image and text latency: 0.021 sec
2025-06-11 07:38:34 [INFO] routes: 0.02120828628540039
2025-06-11 07:38:40 [INFO] routes: /image and text latency: 0.014 sec
2025-06-11 07:38:40 [INFO] routes: 0.014165878295898438
2025-06-11 07:50:57 [INFO] routes: /image and text latency: 0.021 sec
2025-06-11 07:50:57 [INFO] routes: 0.02194356918334961
2025-06-11 12:46:14 [INFO] routes: /image and text latency: 0.098 sec
2025-06-11 12:46:14 [INFO] routes: 0.0988306999206543
2025-06-11 12:47:33 [INFO] routes: /image and text latency: 0.010 sec
2025-06-11 12:47:33 [INFO] routes: 0.010007858276367188
2025-06-11 12:52:36 [INFO] routes: /image and text latency: 0.007 sec
2025-06-11 12:52:36 [INFO] routes: 0.007756948471069336
2025-06-11 12:57:02 [INFO] routes: /image and text latency: 0.095 sec
2025-06-11 12:57:02 [INFO] routes: 0.09476232528686523
2025-06-11 13:02:43 [INFO] routes: /image and text latency: 175.724 sec
2025-06-11 13:02:43 [INFO] routes: 175.7337942123413
2025-06-11 13:02:43 [INFO] routes: /image and text latency: 173.418 sec
2025-06-11 13:02:43 [INFO] routes: 173.4184865951538
2025-06-11 13:10:39 [INFO] routes: /image and text latency: 0.015 sec
2025-06-11 13:10:39 [INFO] routes: 0.015344858169555664
2025-06-11 13:52:09 [INFO] routes: /image and text latency: 0.035 sec
2025-06-11 13:52:09 [INFO] routes: 0.03610968589782715
2025-06-11 13:58:48 [INFO] routes: /image and text latency: 0.015 sec
2025-06-11 13:58:48 [INFO] routes: 0.01554417610168457
2025-06-11 13:59:50 [INFO] routes: /image and text latency: 0.015 sec
2025-06-11 13:59:50 [INFO] routes: 0.014725923538208008
2025-06-11 14:11:56 [INFO] routes: /image and text latency: 0.014 sec
2025-06-11 14:11:56 [INFO] routes: 0.014538049697875977
2025-06-11 14:12:04 [INFO] routes: /image and text latency: 0.008 sec
2025-06-11 14:12:04 [INFO] routes: 0.007726907730102539
2025-06-11 14:12:05 [INFO] routes: /image and text latency: 0.007 sec
2025-06-11 14:12:05 [INFO] routes: 0.007220745086669922
2025-06-11 14:12:05 [INFO] routes: /image and text latency: 0.051 sec
2025-06-11 14:12:05 [INFO] routes: 0.05085444450378418
2025-06-11 14:12:05 [INFO] routes: /image and text latency: 0.071 sec
2025-06-11 14:12:05 [INFO] routes: 0.07155346870422363
2025-06-11 14:12:06 [INFO] routes: /image and text latency: 0.098 sec
2025-06-11 14:12:06 [INFO] routes: 0.0979154109954834
2025-06-11 14:12:06 [INFO] routes: /image and text latency: 0.066 sec
2025-06-11 14:12:06 [INFO] routes: 0.06641864776611328
2025-06-11 14:12:09 [INFO] routes: /image and text latency: 0.054 sec
2025-06-11 14:12:09 [INFO] routes: 0.05466055870056152
2025-06-11 14:12:09 [INFO] routes: /image and text latency: 0.176 sec
2025-06-11 14:12:09 [INFO] routes: 0.1766350269317627
2025-06-11 14:12:09 [INFO] routes: /image and text latency: 0.186 sec
2025-06-11 14:12:09 [INFO] routes: 0.1862788200378418
2025-06-11 14:12:09 [INFO] routes: /image and text latency: 0.144 sec
2025-06-11 14:12:09 [INFO] routes: 0.14415431022644043
2025-06-11 14:13:08 [INFO] routes: /image and text latency: 0.086 sec
2025-06-11 14:13:08 [INFO] routes: 0.08609867095947266
2025-06-11 14:19:31 [INFO] routes: /image and text latency: 0.014 sec
2025-06-11 14:19:31 [INFO] routes: 0.013994693756103516
2025-06-11 14:21:37 [INFO] routes: /image and text latency: 0.012 sec
2025-06-11 14:21:37 [INFO] routes: 0.012631416320800781
2025-06-11 14:27:24 [INFO] routes: /image and text latency: 0.021 sec
2025-06-11 14:27:24 [INFO] routes: 0.02175426483154297
2025-06-11 14:30:32 [INFO] routes: /image and text latency: 0.010 sec
2025-06-11 14:30:32 [INFO] routes: 0.009865760803222656
2025-06-11 14:34:11 [INFO] routes: /image and text latency: 0.015 sec
2025-06-11 14:34:11 [INFO] routes: 0.015236854553222656
2025-06-11 14:43:42 [INFO] routes: /image and text latency: 0.009 sec
2025-06-11 14:43:42 [INFO] routes: 0.009002923965454102
2025-06-11 14:57:00 [INFO] routes: /image and text latency: 0.011 sec
2025-06-11 14:57:00 [INFO] routes: 0.010793209075927734
2025-06-11 15:01:37 [INFO] routes: /image and text latency: 0.018 sec
2025-06-11 15:01:37 [INFO] routes: 0.018586158752441406
2025-06-11 15:10:53 [INFO] routes: /image and text latency: 0.018 sec
2025-06-11 15:10:53 [INFO] routes: 0.01817464828491211
2025-06-12 06:44:12 [ERROR] routes: Error in /image: real_time_image_generator() takes 3 positional arguments but 4 were given
2025-06-12 06:45:46 [ERROR] routes: Error in /image: real_time_image_generator() takes 3 positional arguments but 4 were given
2025-06-12 06:45:58 [ERROR] routes: Error in /image: real_time_image_generator() takes 3 positional arguments but 4 were given
2025-06-12 06:47:08 [ERROR] routes: Error in /image: real_time_image_generator() takes 3 positional arguments but 4 were given
2025-06-12 06:49:15 [ERROR] routes: Error in /image: real_time_image_generator() takes 3 positional arguments but 4 were given
2025-06-12 06:49:48 [ERROR] routes: Error in /image: real_time_image_generator() takes 3 positional arguments but 4 were given
2025-06-12 06:51:04 [ERROR] routes: Error in /image: real_time_image_generator() takes 3 positional arguments but 4 were given
2025-06-12 06:51:05 [ERROR] routes: Error in /image: real_time_image_generator() takes 3 positional arguments but 4 were given
2025-06-12 06:51:05 [ERROR] routes: Error in /image: real_time_image_generator() takes 3 positional arguments but 4 were given
2025-06-12 06:51:33 [ERROR] routes: Error in /image: real_time_image_generator() takes 3 positional arguments but 4 were given
2025-06-15 09:20:04 [ERROR] routes: Error in /image and text: unhandled errors in a TaskGroup (1 sub-exception)
2025-06-15 09:23:25 [ERROR] routes: Error in /image and text: unhandled errors in a TaskGroup (1 sub-exception)
2025-06-16 06:58:53 [ERROR] routes: Error in /text: real_time_text_generator() missing 1 required positional argument: 'in_time'
2025-06-16 07:00:24 [ERROR] routes: Error in /text: Object of type coroutine is not JSON serializable
2025-06-16 07:01:16 [ERROR] routes: Error in /text: Object of type coroutine is not JSON serializable
2025-06-16 07:07:10 [ERROR] routes: Error in /image: Object of type coroutine is not JSON serializable
2025-06-16 07:07:45 [ERROR] routes: Error in /image: Object of type coroutine is not JSON serializable
2025-06-16 07:13:51 [ERROR] routes: Error in /image: [Errno 2] No such file or directory: 'Ushindi Laundry Bar.png'
2025-06-16 11:54:19 [ERROR] routes: Error in /image: Error code: 401 - {'error': {'message': 'Incorrect API key provided: sk-proj-********************************************************************************************************************************************************5w0A. You can find your API key at https://platform.openai.com/account/api-keys.', 'type': 'invalid_request_error', 'param': None, 'code': 'invalid_api_key'}}
2025-06-18 09:30:33 [ERROR] routes: ðŸ”¥ UNCAUGHT ERROR in /image_and_text_new: unhandled errors in a TaskGroup (1 sub-exception)
  + Exception Group Traceback (most recent call last):
  |   File "/home/delin/Coding/pwani_oil/utils/routes.py", line 154, in image_and_text_output
  |     async with asyncio.TaskGroup() as tg:
  |                ^^^^^^^^^^^^^^^^^^^
  |   File "/home/delin/anaconda3/envs/AI_projects/lib/python3.12/asyncio/taskgroups.py", line 71, in __aexit__
  |     return await self._aexit(et, exc)
  |            ^^^^^^^^^^^^^^^^^^^^^^^^^^
  |   File "/home/delin/anaconda3/envs/AI_projects/lib/python3.12/asyncio/taskgroups.py", line 164, in _aexit
  |     raise BaseExceptionGroup(
  | ExceptionGroup: unhandled errors in a TaskGroup (1 sub-exception)
  +-+---------------- 1 ----------------
    | Traceback (most recent call last):
    |   File "/home/delin/Coding/pwani_oil/llm/image_rethink.py", line 103, in image_llm_new
    |     prompt= await  structured_llm.ainvoke(messages)
    |             ^^^^^^^^^^^^^^^^^^^^^^^^^^^^^^^^^^^^^^^
    |   File "/home/delin/anaconda3/envs/AI_projects/lib/python3.12/site-packages/langchain_core/runnables/base.py", line 3089, in ainvoke
    |     input = await asyncio.create_task(part(), context=context)  # type: ignore
    |             ^^^^^^^^^^^^^^^^^^^^^^^^^^^^^^^^^^^^^^^^^^^^^^^^^^
    |   File "/home/delin/anaconda3/envs/AI_projects/lib/python3.12/site-packages/langchain_core/runnables/base.py", line 5453, in ainvoke
    |     return await self.bound.ainvoke(
    |            ^^^^^^^^^^^^^^^^^^^^^^^^^
    |   File "/home/delin/anaconda3/envs/AI_projects/lib/python3.12/site-packages/langchain_core/language_models/chat_models.py", line 353, in ainvoke
    |     llm_result = await self.agenerate_prompt(
    |                  ^^^^^^^^^^^^^^^^^^^^^^^^^^^^
    |   File "/home/delin/anaconda3/envs/AI_projects/lib/python3.12/site-packages/langchain_core/language_models/chat_models.py", line 905, in agenerate_prompt
    |     return await self.agenerate(
    |            ^^^^^^^^^^^^^^^^^^^^^
    |   File "/home/delin/anaconda3/envs/AI_projects/lib/python3.12/site-packages/langchain_core/language_models/chat_models.py", line 863, in agenerate
    |     raise exceptions[0]
    |   File "/home/delin/anaconda3/envs/AI_projects/lib/python3.12/site-packages/langchain_core/language_models/chat_models.py", line 1033, in _agenerate_with_cache
    |     result = await self._agenerate(
    |              ^^^^^^^^^^^^^^^^^^^^^^
    |   File "/home/delin/anaconda3/envs/AI_projects/lib/python3.12/site-packages/langchain_openai/chat_models/base.py", line 1129, in _agenerate
    |     response = await self.root_async_client.beta.chat.completions.parse(
    |                ^^^^^^^^^^^^^^^^^^^^^^^^^^^^^^^^^^^^^^^^^^^^^^^^^^^^^^^^^
    |   File "/home/delin/anaconda3/envs/AI_projects/lib/python3.12/site-packages/openai/resources/beta/chat/completions.py", line 437, in parse
    |     return await self._post(
    |            ^^^^^^^^^^^^^^^^^
    |   File "/home/delin/anaconda3/envs/AI_projects/lib/python3.12/site-packages/openai/_base_client.py", line 1767, in post
    |     return await self.request(cast_to, opts, stream=stream, stream_cls=stream_cls)
    |            ^^^^^^^^^^^^^^^^^^^^^^^^^^^^^^^^^^^^^^^^^^^^^^^^^^^^^^^^^^^^^^^^^^^^^^^
    |   File "/home/delin/anaconda3/envs/AI_projects/lib/python3.12/site-packages/openai/_base_client.py", line 1461, in request
    |     return await self._request(
    |            ^^^^^^^^^^^^^^^^^^^^
    |   File "/home/delin/anaconda3/envs/AI_projects/lib/python3.12/site-packages/openai/_base_client.py", line 1562, in _request
    |     raise self._make_status_error_from_response(err.response) from None
    | openai.AuthenticationError: Error code: 401 - {'error': {'message': 'Incorrect API key provided: sk-proj-********************************************************************************************************************************************************5w0A. You can find your API key at https://platform.openai.com/account/api-keys.', 'type': 'invalid_request_error', 'param': None, 'code': 'invalid_api_key'}}
    +------------------------------------
2025-06-18 09:30:51 [ERROR] routes: ðŸ”¥ UNCAUGHT ERROR in /image_and_text_new: unhandled errors in a TaskGroup (1 sub-exception)
  + Exception Group Traceback (most recent call last):
  |   File "/home/delin/Coding/pwani_oil/utils/routes.py", line 154, in image_and_text_output
  |     async with asyncio.TaskGroup() as tg:
  |                ^^^^^^^^^^^^^^^^^^^
  |   File "/home/delin/anaconda3/envs/AI_projects/lib/python3.12/asyncio/taskgroups.py", line 71, in __aexit__
  |     return await self._aexit(et, exc)
  |            ^^^^^^^^^^^^^^^^^^^^^^^^^^
  |   File "/home/delin/anaconda3/envs/AI_projects/lib/python3.12/asyncio/taskgroups.py", line 164, in _aexit
  |     raise BaseExceptionGroup(
  | ExceptionGroup: unhandled errors in a TaskGroup (1 sub-exception)
  +-+---------------- 1 ----------------
    | Traceback (most recent call last):
    |   File "/home/delin/Coding/pwani_oil/llm/image_rethink.py", line 103, in image_llm_new
    |     prompt= await  structured_llm.ainvoke(messages)
    |             ^^^^^^^^^^^^^^^^^^^^^^^^^^^^^^^^^^^^^^^
    |   File "/home/delin/anaconda3/envs/AI_projects/lib/python3.12/site-packages/langchain_core/runnables/base.py", line 3089, in ainvoke
    |     input = await asyncio.create_task(part(), context=context)  # type: ignore
    |             ^^^^^^^^^^^^^^^^^^^^^^^^^^^^^^^^^^^^^^^^^^^^^^^^^^
    |   File "/home/delin/anaconda3/envs/AI_projects/lib/python3.12/site-packages/langchain_core/runnables/base.py", line 5453, in ainvoke
    |     return await self.bound.ainvoke(
    |            ^^^^^^^^^^^^^^^^^^^^^^^^^
    |   File "/home/delin/anaconda3/envs/AI_projects/lib/python3.12/site-packages/langchain_core/language_models/chat_models.py", line 353, in ainvoke
    |     llm_result = await self.agenerate_prompt(
    |                  ^^^^^^^^^^^^^^^^^^^^^^^^^^^^
    |   File "/home/delin/anaconda3/envs/AI_projects/lib/python3.12/site-packages/langchain_core/language_models/chat_models.py", line 905, in agenerate_prompt
    |     return await self.agenerate(
    |            ^^^^^^^^^^^^^^^^^^^^^
    |   File "/home/delin/anaconda3/envs/AI_projects/lib/python3.12/site-packages/langchain_core/language_models/chat_models.py", line 863, in agenerate
    |     raise exceptions[0]
    |   File "/home/delin/anaconda3/envs/AI_projects/lib/python3.12/site-packages/langchain_core/language_models/chat_models.py", line 1033, in _agenerate_with_cache
    |     result = await self._agenerate(
    |              ^^^^^^^^^^^^^^^^^^^^^^
    |   File "/home/delin/anaconda3/envs/AI_projects/lib/python3.12/site-packages/langchain_openai/chat_models/base.py", line 1129, in _agenerate
    |     response = await self.root_async_client.beta.chat.completions.parse(
    |                ^^^^^^^^^^^^^^^^^^^^^^^^^^^^^^^^^^^^^^^^^^^^^^^^^^^^^^^^^
    |   File "/home/delin/anaconda3/envs/AI_projects/lib/python3.12/site-packages/openai/resources/beta/chat/completions.py", line 437, in parse
    |     return await self._post(
    |            ^^^^^^^^^^^^^^^^^
    |   File "/home/delin/anaconda3/envs/AI_projects/lib/python3.12/site-packages/openai/_base_client.py", line 1767, in post
    |     return await self.request(cast_to, opts, stream=stream, stream_cls=stream_cls)
    |            ^^^^^^^^^^^^^^^^^^^^^^^^^^^^^^^^^^^^^^^^^^^^^^^^^^^^^^^^^^^^^^^^^^^^^^^
    |   File "/home/delin/anaconda3/envs/AI_projects/lib/python3.12/site-packages/openai/_base_client.py", line 1461, in request
    |     return await self._request(
    |            ^^^^^^^^^^^^^^^^^^^^
    |   File "/home/delin/anaconda3/envs/AI_projects/lib/python3.12/site-packages/openai/_base_client.py", line 1562, in _request
    |     raise self._make_status_error_from_response(err.response) from None
    | openai.AuthenticationError: Error code: 401 - {'error': {'message': 'Incorrect API key provided: sk-proj-********************************************************************************************************************************************************5w0A. You can find your API key at https://platform.openai.com/account/api-keys.', 'type': 'invalid_request_error', 'param': None, 'code': 'invalid_api_key'}}
    +------------------------------------
2025-06-18 09:31:24 [ERROR] routes: ðŸ”¥ UNCAUGHT ERROR in /image_and_text_new: unhandled errors in a TaskGroup (1 sub-exception)
  + Exception Group Traceback (most recent call last):
  |   File "/home/delin/Coding/pwani_oil/utils/routes.py", line 154, in image_and_text_output
  |     async with asyncio.TaskGroup() as tg:
  |                ^^^^^^^^^^^^^^^^^^^
  |   File "/home/delin/anaconda3/envs/AI_projects/lib/python3.12/asyncio/taskgroups.py", line 71, in __aexit__
  |     return await self._aexit(et, exc)
  |            ^^^^^^^^^^^^^^^^^^^^^^^^^^
  |   File "/home/delin/anaconda3/envs/AI_projects/lib/python3.12/asyncio/taskgroups.py", line 164, in _aexit
  |     raise BaseExceptionGroup(
  | ExceptionGroup: unhandled errors in a TaskGroup (1 sub-exception)
  +-+---------------- 1 ----------------
    | Traceback (most recent call last):
    |   File "/home/delin/Coding/pwani_oil/llm/image_rethink.py", line 103, in image_llm_new
    |     prompt= await  structured_llm.ainvoke(messages)
    |             ^^^^^^^^^^^^^^^^^^^^^^^^^^^^^^^^^^^^^^^
    |   File "/home/delin/anaconda3/envs/AI_projects/lib/python3.12/site-packages/langchain_core/runnables/base.py", line 3089, in ainvoke
    |     input = await asyncio.create_task(part(), context=context)  # type: ignore
    |             ^^^^^^^^^^^^^^^^^^^^^^^^^^^^^^^^^^^^^^^^^^^^^^^^^^
    |   File "/home/delin/anaconda3/envs/AI_projects/lib/python3.12/site-packages/langchain_core/runnables/base.py", line 5453, in ainvoke
    |     return await self.bound.ainvoke(
    |            ^^^^^^^^^^^^^^^^^^^^^^^^^
    |   File "/home/delin/anaconda3/envs/AI_projects/lib/python3.12/site-packages/langchain_core/language_models/chat_models.py", line 353, in ainvoke
    |     llm_result = await self.agenerate_prompt(
    |                  ^^^^^^^^^^^^^^^^^^^^^^^^^^^^
    |   File "/home/delin/anaconda3/envs/AI_projects/lib/python3.12/site-packages/langchain_core/language_models/chat_models.py", line 905, in agenerate_prompt
    |     return await self.agenerate(
    |            ^^^^^^^^^^^^^^^^^^^^^
    |   File "/home/delin/anaconda3/envs/AI_projects/lib/python3.12/site-packages/langchain_core/language_models/chat_models.py", line 863, in agenerate
    |     raise exceptions[0]
    |   File "/home/delin/anaconda3/envs/AI_projects/lib/python3.12/site-packages/langchain_core/language_models/chat_models.py", line 1033, in _agenerate_with_cache
    |     result = await self._agenerate(
    |              ^^^^^^^^^^^^^^^^^^^^^^
    |   File "/home/delin/anaconda3/envs/AI_projects/lib/python3.12/site-packages/langchain_openai/chat_models/base.py", line 1129, in _agenerate
    |     response = await self.root_async_client.beta.chat.completions.parse(
    |                ^^^^^^^^^^^^^^^^^^^^^^^^^^^^^^^^^^^^^^^^^^^^^^^^^^^^^^^^^
    |   File "/home/delin/anaconda3/envs/AI_projects/lib/python3.12/site-packages/openai/resources/beta/chat/completions.py", line 437, in parse
    |     return await self._post(
    |            ^^^^^^^^^^^^^^^^^
    |   File "/home/delin/anaconda3/envs/AI_projects/lib/python3.12/site-packages/openai/_base_client.py", line 1767, in post
    |     return await self.request(cast_to, opts, stream=stream, stream_cls=stream_cls)
    |            ^^^^^^^^^^^^^^^^^^^^^^^^^^^^^^^^^^^^^^^^^^^^^^^^^^^^^^^^^^^^^^^^^^^^^^^
    |   File "/home/delin/anaconda3/envs/AI_projects/lib/python3.12/site-packages/openai/_base_client.py", line 1461, in request
    |     return await self._request(
    |            ^^^^^^^^^^^^^^^^^^^^
    |   File "/home/delin/anaconda3/envs/AI_projects/lib/python3.12/site-packages/openai/_base_client.py", line 1562, in _request
    |     raise self._make_status_error_from_response(err.response) from None
    | openai.AuthenticationError: Error code: 401 - {'error': {'message': 'Incorrect API key provided: sk-proj-********************************************************************************************************************************************************5w0A. You can find your API key at https://platform.openai.com/account/api-keys.', 'type': 'invalid_request_error', 'param': None, 'code': 'invalid_api_key'}}
    +------------------------------------
2025-06-18 09:32:49 [ERROR] routes: ðŸ”¥ UNCAUGHT ERROR in /image_and_text_new: unhandled errors in a TaskGroup (1 sub-exception)
  + Exception Group Traceback (most recent call last):
  |   File "/home/delin/Coding/pwani_oil/utils/routes.py", line 154, in image_and_text_output
  |     async with asyncio.TaskGroup() as tg:
  |                ^^^^^^^^^^^^^^^^^^^
  |   File "/home/delin/anaconda3/envs/AI_projects/lib/python3.12/asyncio/taskgroups.py", line 71, in __aexit__
  |     return await self._aexit(et, exc)
  |            ^^^^^^^^^^^^^^^^^^^^^^^^^^
  |   File "/home/delin/anaconda3/envs/AI_projects/lib/python3.12/asyncio/taskgroups.py", line 164, in _aexit
  |     raise BaseExceptionGroup(
  | ExceptionGroup: unhandled errors in a TaskGroup (1 sub-exception)
  +-+---------------- 1 ----------------
    | Traceback (most recent call last):
    |   File "/home/delin/Coding/pwani_oil/llm/image_rethink.py", line 103, in image_llm_new
    |     prompt= await  structured_llm.ainvoke(messages)
    |             ^^^^^^^^^^^^^^^^^^^^^^^^^^^^^^^^^^^^^^^
    |   File "/home/delin/anaconda3/envs/AI_projects/lib/python3.12/site-packages/langchain_core/runnables/base.py", line 3089, in ainvoke
    |     input = await asyncio.create_task(part(), context=context)  # type: ignore
    |             ^^^^^^^^^^^^^^^^^^^^^^^^^^^^^^^^^^^^^^^^^^^^^^^^^^
    |   File "/home/delin/anaconda3/envs/AI_projects/lib/python3.12/site-packages/langchain_core/runnables/base.py", line 5453, in ainvoke
    |     return await self.bound.ainvoke(
    |            ^^^^^^^^^^^^^^^^^^^^^^^^^
    |   File "/home/delin/anaconda3/envs/AI_projects/lib/python3.12/site-packages/langchain_core/language_models/chat_models.py", line 353, in ainvoke
    |     llm_result = await self.agenerate_prompt(
    |                  ^^^^^^^^^^^^^^^^^^^^^^^^^^^^
    |   File "/home/delin/anaconda3/envs/AI_projects/lib/python3.12/site-packages/langchain_core/language_models/chat_models.py", line 905, in agenerate_prompt
    |     return await self.agenerate(
    |            ^^^^^^^^^^^^^^^^^^^^^
    |   File "/home/delin/anaconda3/envs/AI_projects/lib/python3.12/site-packages/langchain_core/language_models/chat_models.py", line 863, in agenerate
    |     raise exceptions[0]
    |   File "/home/delin/anaconda3/envs/AI_projects/lib/python3.12/site-packages/langchain_core/language_models/chat_models.py", line 1033, in _agenerate_with_cache
    |     result = await self._agenerate(
    |              ^^^^^^^^^^^^^^^^^^^^^^
    |   File "/home/delin/anaconda3/envs/AI_projects/lib/python3.12/site-packages/langchain_openai/chat_models/base.py", line 1129, in _agenerate
    |     response = await self.root_async_client.beta.chat.completions.parse(
    |                ^^^^^^^^^^^^^^^^^^^^^^^^^^^^^^^^^^^^^^^^^^^^^^^^^^^^^^^^^
    |   File "/home/delin/anaconda3/envs/AI_projects/lib/python3.12/site-packages/openai/resources/beta/chat/completions.py", line 437, in parse
    |     return await self._post(
    |            ^^^^^^^^^^^^^^^^^
    |   File "/home/delin/anaconda3/envs/AI_projects/lib/python3.12/site-packages/openai/_base_client.py", line 1767, in post
    |     return await self.request(cast_to, opts, stream=stream, stream_cls=stream_cls)
    |            ^^^^^^^^^^^^^^^^^^^^^^^^^^^^^^^^^^^^^^^^^^^^^^^^^^^^^^^^^^^^^^^^^^^^^^^
    |   File "/home/delin/anaconda3/envs/AI_projects/lib/python3.12/site-packages/openai/_base_client.py", line 1461, in request
    |     return await self._request(
    |            ^^^^^^^^^^^^^^^^^^^^
    |   File "/home/delin/anaconda3/envs/AI_projects/lib/python3.12/site-packages/openai/_base_client.py", line 1562, in _request
    |     raise self._make_status_error_from_response(err.response) from None
    | openai.AuthenticationError: Error code: 401 - {'error': {'message': 'Incorrect API key provided: sk-proj-********************************************************************************************************************************************************5w0A. You can find your API key at https://platform.openai.com/account/api-keys.', 'type': 'invalid_request_error', 'param': None, 'code': 'invalid_api_key'}}
    +------------------------------------
